# Promise

프로미스는 비동기 작업을 조금 더 편하게 처리할 수 있도록 ES6에 도입된 기능

- 이전에는 비동기 작업을 처리할 때 콜백 함수로 처리해야 했었는데, 콜백 함수로 처리하면 비동기 작업이 많아질 경우 코드가 난잡해짐
- 숫자 n을 파라미터로 받아와서 다섯번에 걸쳐 1초마다 1씩 더해서 출력하는 작업을 setTimeout으로 구현

  ```js
  function increaseAndPrint(n, callback) {
    setTimeout(() => {
      const increased = n + 1;
      console.log(increased);
      if (callback) {
        callback(increased);
      }
    }, 1000);
  }

  increaseAndPrint(0, (n) => {
    increaseAndPrint(n, (n) => {
      increaseAndPrint(n, (n) => {
        increaseAndPrint(n, (n) => {
          increaseAndPrint(n, (n) => {
            console.log("끝!");
          });
        });
      });
    });
  });
  /*
  1
  2
  3
  4
  5
  끝!
  */
  ```

  - 이런 복잡한 코드를 Callback Hell(콜백지옥) 이라고 부름

- 비동기적으로 처리해야 하는 일이 많아질수록, 코드의 깊이가 계속 깊어지는 현상 발생
- Promise를 사용하면 코드가 깊어지는 현상을 방지할 수 있음

## Promise 만들기

- Promise는 다음과 같이 만듦
  ```js
  const myPromise = new Promise((resolve, reject) => {
    // 구현..
  });
  ```
- Promise는 성공할 수도 있고, 실패할 수도 있음
  - 성공할 때는 resolve를 호출
  - 실패할 때는 reject를 호출
- 먼저 성공시키는 상황 예제

  ```js
  const myPromise = new Promise((resolve, reject) => {
    setTimeout(() => {
      resolve(1);
    }, 1000);
  });

  myPromise.then((n) => {
    console.log(n);
  });
  // 1
  ```

- resolve를 호출할 때 특정 값을 파라미터로 넣어주면, 이 값을 작업이 끝나고 나서 사용 가능
- 작업이 끝나고 또 다른 작업을 해야할 때는 Promise뒤에 `.then(...)`을 붙여서 사용

- 실패되는 상황 예제

  ```js
  const myPromise = new Promise((resolve, reject) => {
    setTimeout(() => {
      reject(new Error());
    }, 1000);
  });

  myPromise
    .then((n) => {
      console.log(n);
    })
    .catch((error) => {
      console.log(error);
    });

  // 에러 발생
  ```

- 실패하는 상황에서는 `reject`를 사용하고 `.catch`를 통해 실패했을 시 수행할 작업을 설정
- 이제 Promise를 만드는 함수를 작성

  ```js
  function increaseAndPrint(n) {
    return new Promise((resolve, reject) => {
      setTimeout(() => {
        const value = n + 1;
        if (value === 5) {
          const error = new Error();
          error.name = "ValueIsFiveError";
          reject(error);
          return;
        }
        console.log(value);
        resolve(value);
      }, 1000);
    });
  }

  increasAndPrint(0).then((n) => {
    console.log("result: ", n);
  });

  /*
  1
  result: 1
  */
  ```

- 여기까지만 보면 콜백함수와 다를게 없다고 생각할 수 있지만, promise의 속성 중 만약 then내부에 넣은 함수에서 또 Promise를 리턴하게 되면 연달아서 사용 가능!

  ```js
  function increaseAndPrint(n) {
    return new Promise((resolve, reject) => {
      setTimeout(() => {
        const value = n + 1;
        if (value === 5) {
          const error = new Error();
          error.name = "ValueIsFiveError";
          reject(error);
          return;
        }
        console.log(value);
        resolve(value);
      }, 1000);
    });
  }

  increaseAndPrint(0)
    .then((n) => {
      return increaseAndPrint(n);
    })
    .then((n) => {
      return increaseAndPrint(n);
    })
    .then((n) => {
      return increaseAndPrint(n);
    })
    .then((n) => {
      return increaseAndPrint(n);
    })
    .then((n) => {
      return increaseAndPrint(n);
    })
    .catch((e) => {
      console.error(e);
    });
  /*
  1
  2
  3
  4
  ValueIsFiveError 발생
  */
  ```

- 위 코드의 함수 호출 부분을 이렇게 정리 가능

  ```js
  function increaseAndPrint(n) {
    return new Promise((resolve, reject) => {
      setTimeout(() => {
        const value = n + 1;
        if (value === 5) {
          const error = new Error();
          error.name = "ValueIsFiveError";
          reject(error);
          return;
        }
        console.log(value);
        resolve(value);
      }, 1000);
    });
  }

  increaseAndPrint(0)
    .then(increaseAndPrint)
    .then(increaseAndPrint)
    .then(increaseAndPrint)
    .then(increaseAndPrint)
    .then(increaseAndPrint)
    .catch((e) => {
      console.error(e);
    });
  /*
  1
  2
  3
  4
  ValueIsFiveError 발생
  */
  ```

- Promise를 사용하면, 비동기 작업의 개수가 많아져도 코드의 깊이가 깊어지지 않게 됨
- 하지만 단점이 있음
  - 에러를 잡을 때 몇번째에서 발생했는지 알아내기 어려움
  - 특정 조건에 따라 분기를 나누는 것이 어려움
  - 특정 값을 공유하면서 작업을 처리하기 까다로움
- async/await를 사용하면 이러한 문제점을 해결할 수 있음
